Workbook

Sheet Functional Requirements
B1: As a | C1: I should be able to | D1: Comment | E1: Marks | F1: Sprint | G1: Member
A2: 1 | B2: Student/Staff/TA/Professor | C2: sign up with my email, password, First name, Last name and student/staff id | D2: Eveyone should use their GUC email while signing up Admins and Event offices donnot sign up | E2: 2.5 | F2: 1 | G2: =IF(ISNUMBER(MATCH(A2, 'Sprint 1'!A:A, 0)), VLOOKUP(A2, 'Sprint 1'!A:G, 7, FALSE), VLOOKUP(A2, 'Sprint 2'!A:G, 7, FALSE)) -> Ali Ussama Youssef
A3: 2 | B3: Vendor | C3: sign up with an email, password, company name | E3: 2 | F3: 1 | G3: =IF(ISNUMBER(MATCH(A3, 'Sprint 1'!A:A, 0)), VLOOKUP(A3, 'Sprint 1'!A:G, 7, FALSE), VLOOKUP(A3, 'Sprint 2'!A:G, 7, FALSE)) -> Ali Ussama Youssef
A4: 3 | B4: Vendor | C4: upload tax card and logo to prove company validity | E4: 2 | F4: 2 | G4: =IF(ISNUMBER(MATCH(A4, 'Sprint 1'!A:A, 0)), VLOOKUP(A4, 'Sprint 1'!A:G, 7, FALSE), VLOOKUP(A4, 'Sprint 2'!A:G, 7, FALSE)) -> Ali Ussama Youssef
A5: 4 | B5: Student | C5: receive a verification email after registration | D5: The verification mail should contain a verification link that automatically redirects me to the login page If I didnot click on the link I shouldnt be verified hence the login should fail | E5: 2 | F5: 2 | G5: =IF(ISNUMBER(MATCH(A5, 'Sprint 1'!A:A, 0)), VLOOKUP(A5, 'Sprint 1'!A:G, 7, FALSE), VLOOKUP(A5, 'Sprint 2'!A:G, 7, FALSE)) -> Ali Ussama Youssef
A6: 5 | B6: Admin | C6: insert the correct role for each of Staff/ TA/ Professor after receiving their request to register and then sends a verification mail | E6: 2 | F6: 1 | G6: =IF(ISNUMBER(MATCH(A6, 'Sprint 1'!A:A, 0)), VLOOKUP(A6, 'Sprint 1'!A:G, 7, FALSE), VLOOKUP(A6, 'Sprint 2'!A:G, 7, FALSE)) -> Ahmed Mohamed Elsayed
A7: 6 | B7: Staff/ TA/ Professor | C7: receive a verification email after the admin verifies their role | D7: The verification mail should contain a verification link that automatically redirects me to the login page If I did not click on the link I shouldn't be verified, hence the login should fail | E7: 3 | F7: 1 | G7: =IF(ISNUMBER(MATCH(A7, 'Sprint 1'!A:A, 0)), VLOOKUP(A7, 'Sprint 1'!A:G, 7, FALSE), VLOOKUP(A7, 'Sprint 2'!A:G, 7, FALSE)) -> Ahmed Mohamed Elsayed
A8: 7 | B8: Admin | C8: create other admin/Event Office accounts including the admin name, email and password | E8: 2 | F8: 1 | G8: =IF(ISNUMBER(MATCH(A8, 'Sprint 1'!A:A, 0)), VLOOKUP(A8, 'Sprint 1'!A:G, 7, FALSE), VLOOKUP(A8, 'Sprint 2'!A:G, 7, FALSE)) -> Abdelhamid Sameh Abdelhamid
A9: 8 | B9: Admin | C9: delete other admin/Event Office accounts | E9: 2 | F9: 1 | G9: =IF(ISNUMBER(MATCH(A9, 'Sprint 1'!A:A, 0)), VLOOKUP(A9, 'Sprint 1'!A:G, 7, FALSE), VLOOKUP(A9, 'Sprint 2'!A:G, 7, FALSE)) -> Abdelhamid Sameh Abdelhamid
A10: 9 | B10: Student/Staff/ Events Office/TA/ Professor/ Admin | C10: login with my email and password | D10: Eveyone should use their GUC email except Companies and Vendors | E10: 3 | F10: 1 | G10: =IF(ISNUMBER(MATCH(A10, 'Sprint 1'!A:A, 0)), VLOOKUP(A10, 'Sprint 1'!A:G, 7, FALSE), VLOOKUP(A10, 'Sprint 2'!A:G, 7, FALSE)) -> Yehia Wael Raafat
A11: 10 | B11: Student/Staff/ Events Office/TA/ Professor/ Admin | C11: logout from my account successfully | E11: 3 | F11: 1 | G11: =IF(ISNUMBER(MATCH(A11, 'Sprint 1'!A:A, 0)), VLOOKUP(A11, 'Sprint 1'!A:G, 7, FALSE), VLOOKUP(A11, 'Sprint 2'!A:G, 7, FALSE)) -> Yehia Wael Raafat
A12: 11 | B12: Student/Staff/ Events Office/TA/ Professor/ Admin | C12: view all availabe events that are coming up and all their details including the vendors that will participate (for bazaars and booths) | D12: Events are workshops, trips, bazaars, booths in platform, conferences | E12: 3 | F12: 1 | G12: =IF(ISNUMBER(MATCH(A12, 'Sprint 1'!A:A, 0)), VLOOKUP(A12, 'Sprint 1'!A:G, 7, FALSE), VLOOKUP(A12, 'Sprint 2'!A:G, 7, FALSE)) -> Yehia Wael Raafat
A13: 12 | B13: Student/Staff/ Events Office/TA/ Professor/ Admin | C13: search the events by a specific name(Professor name/Event name) or type | E13: 3 | F13: 1 | G13: =IF(ISNUMBER(MATCH(A13, 'Sprint 1'!A:A, 0)), VLOOKUP(A13, 'Sprint 1'!A:G, 7, FALSE), VLOOKUP(A13, 'Sprint 2'!A:G, 7, FALSE)) -> Yehia Wael Raafat
A14: 13 | B14: Student/Staff/ Events Office/TA/ Professor/ Admin | C14: filter the events by a specific name(Professor name incase of a workshop or a conference), location, type or date | E14: 3 | F14: 2 | G14: =IF(ISNUMBER(MATCH(A14, 'Sprint 1'!A:A, 0)), VLOOKUP(A14, 'Sprint 1'!A:G, 7, FALSE), VLOOKUP(A14, 'Sprint 2'!A:G, 7, FALSE)) -> Yehia Wael Raafat
A15: 14 | B15: Student/Staff/ Events Office/TA/ Professor/ Admin | C15: sort the events by date | E15: 3 | F15: 2 | G15: =IF(ISNUMBER(MATCH(A15, 'Sprint 1'!A:A, 0)), VLOOKUP(A15, 'Sprint 1'!A:G, 7, FALSE), VLOOKUP(A15, 'Sprint 2'!A:G, 7, FALSE)) -> Yehia Wael Raafat
A16: 15 | B16: Student/Staff/ TA/ Professor | C16: rate an event that i attended | E16: 2 | F16: 2 | G16: =IF(ISNUMBER(MATCH(A16, 'Sprint 1'!A:A, 0)), VLOOKUP(A16, 'Sprint 1'!A:G, 7, FALSE), VLOOKUP(A16, 'Sprint 2'!A:G, 7, FALSE))
A17: 16 | B17: Student/Staff/TA/ Professor | C17: comment on an event that i attended | E17: 2 | F17: 2 | G17: =IF(ISNUMBER(MATCH(A17, 'Sprint 1'!A:A, 0)), VLOOKUP(A17, 'Sprint 1'!A:G, 7, FALSE), VLOOKUP(A17, 'Sprint 2'!A:G, 7, FALSE))
A18: 17 | B18: Student/Staff/ Events Office/TA/ Professor/ Admin | C18: view all ratings and comments on any event | E18: 3 | F18: 2 | G18: =IF(ISNUMBER(MATCH(A18, 'Sprint 1'!A:A, 0)), VLOOKUP(A18, 'Sprint 1'!A:G, 7, FALSE), VLOOKUP(A18, 'Sprint 2'!A:G, 7, FALSE))
A19: 18 | B19: Admin | C19: delete any inappropriate comments | E19: 2 | F19: 2 | G19: =IF(ISNUMBER(MATCH(A19, 'Sprint 1'!A:A, 0)), VLOOKUP(A19, 'Sprint 1'!A:G, 7, FALSE), VLOOKUP(A19, 'Sprint 2'!A:G, 7, FALSE))
A20: 19 | B20: Admin | C20: block any user | E20: 2 | F20: 2 | G20: =IF(ISNUMBER(MATCH(A20, 'Sprint 1'!A:A, 0)), VLOOKUP(A20, 'Sprint 1'!A:G, 7, FALSE), VLOOKUP(A20, 'Sprint 2'!A:G, 7, FALSE))
A21: 20 | B21: Admin | C21: view a list of all users along with their details and status (active/blocked) | E21: 4 | F21: 1 | G21: =IF(ISNUMBER(MATCH(A21, 'Sprint 1'!A:A, 0)), VLOOKUP(A21, 'Sprint 1'!A:G, 7, FALSE), VLOOKUP(A21, 'Sprint 2'!A:G, 7, FALSE)) -> Ahmed Mohamed Elsayed
A22: 21 | B22: Student/Staff/ Events Office/TA/ Professor | C22: receive a warning email if any of my comments were deleted for being inappropriate | E22: 5 | F22: 2 | G22: =IF(ISNUMBER(MATCH(A22, 'Sprint 1'!A:A, 0)), VLOOKUP(A22, 'Sprint 1'!A:G, 7, FALSE), VLOOKUP(A22, 'Sprint 2'!A:G, 7, FALSE))
A23: 22 | B23: Student/Staff/TA/Professor | C23: add an event to their favorites list | E23: 4 | F23: 2 | G23: =IF(ISNUMBER(MATCH(A23, 'Sprint 1'!A:A, 0)), VLOOKUP(A23, 'Sprint 1'!A:G, 7, FALSE), VLOOKUP(A23, 'Sprint 2'!A:G, 7, FALSE))
A24: 23 | B24: Student/Staff/TA/Professor | C24: view my favorites list | E24: 4 | F24: 2 | G24: =IF(ISNUMBER(MATCH(A24, 'Sprint 1'!A:A, 0)), VLOOKUP(A24, 'Sprint 1'!A:G, 7, FALSE), VLOOKUP(A24, 'Sprint 2'!A:G, 7, FALSE))
... A27: 26 | B27: Student/Staff/TA/Professor | C27: receive a payment receipt via email upon paying | E27: 4 | F27: 2 | G27: =IF(ISNUMBER(MATCH(A27, 'Sprint 1'!A:A, 0)), VLOOKUP(A27, 'Sprint 1'!A:G, 7, FALSE), VLOOKUP(A27, 'Sprint 2'!A:G, 7, FALSE))
A28: 27 | B28: Student/Staff/TA/Professor | C28: view a list of my registered events | D28: Upcoming and past events | E28: 4 | F28: 1 | G28: =IF(ISNUMBER(MATCH(A28, 'Sprint 1'!A:A, 0)), VLOOKUP(A28, 'Sprint 1'!A:G, 7, FALSE), VLOOKUP(A28, 'Sprint 2'!A:G, 7, FALSE)) -> Yehia Wael Raafat
A29: 28 | B29: Student/Staff/TA/Professor | C29: cancel the registration and refund the amount paid on my wallet | D29: cancellation can only be accepted if there are still 2 weeks for the event | E29: 4 | F29: 2 | G29: =IF(ISNUMBER(MATCH(A29, 'Sprint 1'!A:A, 0)), VLOOKUP(A29, 'Sprint 1'!A:G, 7, FALSE), VLOOKUP(A29, 'Sprint 2'!A:G, 7, FALSE))
A30: 29 | B30: Student/Staff/TA/Professor | C30: view amount refunded in my wallet | E30: 4 | F30: 2 | G30: =IF(ISNUMBER(MATCH(A30, 'Sprint 1'!A:A, 0)), VLOOKUP(A30, 'Sprint 1'!A:G, 7, FALSE), VLOOKUP(A30, 'Sprint 2'!A:G, 7, FALSE))
A31: 30 | B31: Student/Staff/TA/Professor | C31: receive a certificate of attendance upon finishing workshop via email | E31: 4 | F31: 2 | G31: =IF(ISNUMBER(MATCH(A31, 'Sprint 1'!A:A, 0)), VLOOKUP(A31, 'Sprint 1'!A:G, 7, FALSE), VLOOKUP(A31, 'Sprint 2'!A:G, 7, FALSE))
A32: 31 | B32: Events Office | C32: create bazaars by adding the bazaar name, start and end date and time, location, short description and registration deadline | E32: 2 | F32: 1 | G32: =IF(ISNUMBER(MATCH(A32, 'Sprint 1'!A:A, 0)), VLOOKUP(A32, 'Sprint 1'!A:G, 7, FALSE), VLOOKUP(A32, 'Sprint 2'!A:G, 7, FALSE)) -> Ahmed Hamdy Mostafa
A33: 32 | B33: Events Office | C33: edit any of the bazaar details entered | D33: Only if the bazar hasn't started yet | E33: 2 | F33: 1 | G33: =IF(ISNUMBER(MATCH(A33, 'Sprint 1'!A:A, 0)), VLOOKUP(A33, 'Sprint 1'!A:G, 7, FALSE), VLOOKUP(A33, 'Sprint 2'!A:G, 7, FALSE)) -> Ahmed Hamdy Mostafa
A34: 33 | B34: Events Office | C34: create trips by adding the trip name, location, price, start and end date and time, short description, capacity, registeration deadline | E34: 2 | F34: 1 | G34: =IF(ISNUMBER(MATCH(A34, 'Sprint 1'!A:A, 0)), VLOOKUP(A34, 'Sprint 1'!A:G, 7, FALSE), VLOOKUP(A34, 'Sprint 2'!A:G, 7, FALSE)) -> Ahmed Hamdy Mostafa
A35: 34 | B35: Events Office | C35: edit any of the trip details | D35: Only if trip start date hasn't passed yet | E35: 2 | F35: 1 | G35: =IF(ISNUMBER(MATCH(A35, 'Sprint 1'!A:A, 0)), VLOOKUP(A35, 'Sprint 1'!A:G, 7, FALSE), VLOOKUP(A35, 'Sprint 2'!A:G, 7, FALSE)) -> Ahmed Hamdy Mostafa
A36: 35 | B36: Professor | C36: create workshops by adding the workshop name, location (GUC Cairo or GUC Berlin), start and end dates and times, short description, full agenda, faculty responsible (MET, IET, etc..), professor(s) participating, required budget, funding source (external or GUC), extra required resources, capacity, registeration deadline | E36: 2 | F36: 1 | G36: =IF(ISNUMBER(MATCH(A36, 'Sprint 1'!A:A, 0)), VLOOKUP(A36, 'Sprint 1'!A:G, 7, FALSE), VLOOKUP(A36, 'Sprint 2'!A:G, 7, FALSE)) -> Ahmed Mohamed Elsayed
A37: 36 | B37: Professor | C37: edit any of the workshop details entered | E37: 2 | F37: 1 | G37: =IF(ISNUMBER(MATCH(A37, 'Sprint 1'!A:A, 0)), VLOOKUP(A37, 'Sprint 1'!A:G, 7, FALSE), VLOOKUP(A37, 'Sprint 2'!A:G, 7, FALSE)) -> Ahmed Mohamed Elsayed
A38: 37 | B38: Professor | C38: view a list of all workshops that i created | E38: 2 | F38: 1 | G38: =IF(ISNUMBER(MATCH(A38, 'Sprint 1'!A:A, 0)), VLOOKUP(A38, 'Sprint 1'!A:G, 7, FALSE), VLOOKUP(A38, 'Sprint 2'!A:G, 7, FALSE)) -> Ahmed Mohamed Elsayed
A39: 38 | B39: Professor | C39: view a list of participants in a workshop that i created and the number of remaining spots | E39: 2 | F39: 2 | G39: =IF(ISNUMBER(MATCH(A39, 'Sprint 1'!A:A, 0)), VLOOKUP(A39, 'Sprint 1'!A:G, 7, FALSE), VLOOKUP(A39, 'Sprint 2'!A:G, 7, FALSE))
A40: 39 | B40: Events Office | C40: receive notifications on the system when doctors submit workshop requests | E40: 2 | F40: 2 | G40: =IF(ISNUMBER(MATCH(A40, 'Sprint 1'!A:A, 0)), VLOOKUP(A40, 'Sprint 1'!A:G, 7, FALSE), VLOOKUP(A40, 'Sprint 2'!A:G, 7, FALSE))
A41: 40 | B41: Events Office | C41: accept and publish workshop created by a professor | E41: 2 | F41: 1 | G41: =IF(ISNUMBER(MATCH(A41, 'Sprint 1'!A:A, 0)), VLOOKUP(A41, 'Sprint 1'!A:G, 7, FALSE), VLOOKUP(A41, 'Sprint 2'!A:G, 7, FALSE)) -> Ali Ussama Youssef
A42: 41 | B42: Events Office | C42: reject workshop | E42: 2 | F42: 1 | G42: =IF(ISNUMBER(MATCH(A42, 'Sprint 1'!A:A, 0)), VLOOKUP(A42, 'Sprint 1'!A:G, 7, FALSE), VLOOKUP(A42, 'Sprint 2'!A:G, 7, FALSE)) -> Ali Ussama Youssef
...

Sheet Sprint 1
B1: As a | C1: I should be able to | D1: Comment | E1: Marks | F1: Sprint | G1: who | H1: done
A2: =IFERROR(__xludf.DUMMYFUNCTION("IFERROR(FILTER('Functional Requirements'!A:F, 'Functional Requirements'!F:F=1), ""No Sprint 1 items"") "),1.0) -> 1 | B2: =IFERROR(__xludf.DUMMYFUNCTION("""COMPUTED_VALUE"""),"Student/Staff/TA/Professor") -> Student/Staff/TA/Professor | C2: =IFERROR(__xludf.DUMMYFUNCTION("""COMPUTED_VALUE"""),"sign up with my email, password, First name, Last name and student/staff id") -> sign up with my email, password, First name, Last name and student/staff id | D2: =IFERROR(__xludf.DUMMYFUNCTION("""COMPUTED_VALUE"""),"Eveyone should use their GUC email while signing up Admins and Event offices donnot sign up") -> Eveyone should use their GUC email while signing up Admins and Event offices donnot sign up | E2: =IFERROR(__xludf.DUMMYFUNCTION("""COMPUTED_VALUE"""),2.5) -> 2.5 | F2: =IFERROR(__xludf.DUMMYFUNCTION("""COMPUTED_VALUE"""),1.0) -> 1 | G2: Ali Ussama Youssef
A3: =IFERROR(__xludf.DUMMYFUNCTION("""COMPUTED_VALUE"""),2.0) -> 2 | B3: =IFERROR(__xludf.DUMMYFUNCTION("""COMPUTED_VALUE"""),"Vendor") -> Vendor | C3: =IFERROR(__xludf.DUMMYFUNCTION("""COMPUTED_VALUE"""),"sign up with an email, password, company name") -> sign up with an email, password, company name | E3: =IFERROR(__xludf.DUMMYFUNCTION("""COMPUTED_VALUE"""),2.0) -> 2 | F3: =IFERROR(__xludf.DUMMYFUNCTION("""COMPUTED_VALUE"""),1.0) -> 1 | G3: Ali Ussama Youssef
A4: =IFERROR(__xludf.DUMMYFUNCTION("""COMPUTED_VALUE"""),5.0) -> 5 | B4: =IFERROR(__xludf.DUMMYFUNCTION("""COMPUTED_VALUE"""),"Admin") -> Admin | C4: =IFERROR(__xludf.DUMMYFUNCTION("""COMPUTED_VALUE"""),"insert the correct role for each of Staff/ TA/ Professor after receiving their request to register and then sends a verification mail") -> insert the correct role for each of Staff/ TA/ Professor after receiving their request to register and then sends a verification mail | E4: =IFERROR(__xludf.DUMMYFUNCTION("""COMPUTED_VALUE"""),2.0) -> 2 | F4: =IFERROR(__xludf.DUMMYFUNCTION("""COMPUTED_VALUE"""),1.0) -> 1 | G4: Ahmed Mohamed Elsayed
A5: =IFERROR(__xludf.DUMMYFUNCTION("""COMPUTED_VALUE"""),6.0) -> 6 | B5: =IFERROR(__xludf.DUMMYFUNCTION("""COMPUTED_VALUE"""),"Staff/ TA/ Professor") -> Staff/ TA/ Professor | C5: =IFERROR(__xludf.DUMMYFUNCTION("""COMPUTED_VALUE"""),"receive a verification email after the admin verifies their role") -> receive a verification email after the admin verifies their role | D5: =IFERROR(__xludf.DUMMYFUNCTION("""COMPUTED_VALUE"""),"The verification mail should contain a verification link that automatically redirects me to the login page If I did not click on the link I shouldn't be verified, hence the login should fail") -> The verification mail should contain a verification link that automatically redirects me to the login page If I did not click on the link I shouldn't be verified, hence the login should fail | E5: =IFERROR(__xludf.DUMMYFUNCTION("""COMPUTED_VALUE"""),3.0) -> 3 | F5: =IFERROR(__xludf.DUMMYFUNCTION("""COMPUTED_VALUE"""),1.0) -> 1 | G5: Ahmed Mohamed Elsayed
A6: =IFERROR(__xludf.DUMMYFUNCTION("""COMPUTED_VALUE"""),7.0) -> 7 | B6: =IFERROR(__xludf.DUMMYFUNCTION("""COMPUTED_VALUE"""),"Admin") -> Admin | C6: =IFERROR(__xludf.DUMMYFUNCTION("""COMPUTED_VALUE"""),"create other admin/Event Office accounts including the admin name, email and password") -> create other admin/Event Office accounts including the admin name, email and password | E6: =IFERROR(__xludf.DUMMYFUNCTION("""COMPUTED_VALUE"""),2.0) -> 2 | F6: =IFERROR(__xludf.DUMMYFUNCTION("""COMPUTED_VALUE"""),1.0) -> 1 | G6: Abdelhamid Sameh Abdelhamid
A7: =IFERROR(__xludf.DUMMYFUNCTION("""COMPUTED_VALUE"""),8.0) -> 8 | B7: =IFERROR(__xludf.DUMMYFUNCTION("""COMPUTED_VALUE"""),"Admin") -> Admin | C7: =IFERROR(__xludf.DUMMYFUNCTION("""COMPUTED_VALUE"""),"delete other admin/Event Office accounts") -> delete other admin/Event Office accounts | E7: =IFERROR(__xludf.DUMMYFUNCTION("""COMPUTED_VALUE"""),2.0) -> 2 | F7: =IFERROR(__xludf.DUMMYFUNCTION("""COMPUTED_VALUE"""),1.0) -> 1 | G7: Abdelhamid Sameh Abdelhamid
A8: =IFERROR(__xludf.DUMMYFUNCTION("""COMPUTED_VALUE"""),9.0) -> 9 | B8: =IFERROR(__xludf.DUMMYFUNCTION("""COMPUTED_VALUE"""),"Student/Staff/ Events Office/TA/ Professor/ Admin") -> Student/Staff/ Events Office/TA/ Professor/ Admin | C8: =IFERROR(__xludf.DUMMYFUNCTION("""COMPUTED_VALUE"""),"login with my email and password") -> login with my email and password | D8: =IFERROR(__xludf.DUMMYFUNCTION("""COMPUTED_VALUE"""),"Eveyone should use their GUC email except Companies and Vendors") -> Eveyone should use their GUC email except Companies and Vendors | E8: =IFERROR(__xludf.DUMMYFUNCTION("""COMPUTED_VALUE"""),3.0) -> 3 | F8: =IFERROR(__xludf.DUMMYFUNCTION("""COMPUTED_VALUE"""),1.0) -> 1 | G8: Yehia Wael Raafat
A9: =IFERROR(__xludf.DUMMYFUNCTION("""COMPUTED_VALUE"""),10.0) -> 10 | B9: =IFERROR(__xludf.DUMMYFUNCTION("""COMPUTED_VALUE"""),"Student/Staff/ Events Office/TA/ Professor/ Admin") -> Student/Staff/ Events Office/TA/ Professor/ Admin | C9: =IFERROR(__xludf.DUMMYFUNCTION("""COMPUTED_VALUE"""),"logout from my account successfully") -> logout from my account successfully | E9: =IFERROR(__xludf.DUMMYFUNCTION("""COMPUTED_VALUE"""),3.0) -> 3 | F9: =IFERROR(__xludf.DUMMYFUNCTION("""COMPUTED_VALUE"""),1.0) -> 1 | G9: Yehia Wael Raafat
A10: =IFERROR(__xludf.DUMMYFUNCTION("""COMPUTED_VALUE"""),11.0) -> 11 | B10: =IFERROR(__xludf.DUMMYFUNCTION("""COMPUTED_VALUE"""),"Student/Staff/ Events Office/TA/ Professor/ Admin") -> Student/Staff/ Events Office/TA/ Professor/ Admin | C10: =IFERROR(__xludf.DUMMYFUNCTION("""COMPUTED_VALUE"""),"view all availabe events that are coming up and all their details including the vendors that will participate (for bazaars and booths)") -> view all availabe events that are coming up and all their details including the vendors that will participate (for bazaars and booths) | D10: =IFERROR(__xludf.DUMMYFUNCTION("""COMPUTED_VALUE"""),"Events are workshops, trips, bazaars, booths in platform, conferences") -> Events are workshops, trips, bazaars, booths in platform, conferences | E10: =IFERROR(__xludf.DUMMYFUNCTION("""COMPUTED_VALUE"""),3.0) -> 3 | F10: =IFERROR(__xludf.DUMMYFUNCTION("""COMPUTED_VALUE"""),1.0) -> 1 | G10: Yehia Wael Raafat
A11: =IFERROR(__xludf.DUMMYFUNCTION("""COMPUTED_VALUE"""),12.0) -> 12 | B11: =IFERROR(__xludf.DUMMYFUNCTION("""COMPUTED_VALUE"""),"Student/Staff/ Events Office/TA/ Professor/ Admin") -> Student/Staff/ Events Office/TA/ Professor/ Admin | C11: =IFERROR(__xludf.DUMMYFUNCTION("""COMPUTED_VALUE"""),"search the events by a specific name(Professor name/Event name) or type") -> search the events by a specific name(Professor name/Event name) or type | E11: =IFERROR(__xludf.DUMMYFUNCTION("""COMPUTED_VALUE"""),3.0) -> 3 | F11: =IFERROR(__xludf.DUMMYFUNCTION("""COMPUTED_VALUE"""),1.0) -> 1 | G11: Yehia Wael Raafat
A12: =IFERROR(__xludf.DUMMYFUNCTION("""COMPUTED_VALUE"""),20.0) -> 20 | B12: =IFERROR(__xludf.DUMMYFUNCTION("""COMPUTED_VALUE"""),"Admin") -> Admin | C12: =IFERROR(__xludf.DUMMYFUNCTION("""COMPUTED_VALUE"""),"view a list of all users along with their details and status (active/blocked)") -> view a list of all users along with their details and status (active/blocked) | E12: =IFERROR(__xludf.DUMMYFUNCTION("""COMPUTED_VALUE"""),4.0) -> 4 | F12: =IFERROR(__xludf.DUMMYFUNCTION("""COMPUTED_VALUE"""),1.0) -> 1 | G12: Ahmed Mohamed Elsayed
A13: =IFERROR(__xludf.DUMMYFUNCTION("""COMPUTED_VALUE"""),24.0) -> 24 | B13: =IFERROR(__xludf.DUMMYFUNCTION("""COMPUTED_VALUE"""),"Student/Staff/TA/Professor") -> Student/Staff/TA/Professor | C13: =IFERROR(__xludf.DUMMYFUNCTION("""COMPUTED_VALUE"""),"register for a workshop/trip using name, mail, student/staff id") -> register for a workshop/trip using name, mail, student/staff id | E13: =IFERROR(__xludf.DUMMYFUNCTION("""COMPUTED_VALUE"""),4.0) -> 4 | F13: =IFERROR(__xludf.DUMMYFUNCTION("""COMPUTED_VALUE"""),1.0) -> 1 | G13: Yehia Wael Raafat
A14: =IFERROR(__xludf.DUMMYFUNCTION("""COMPUTED_VALUE"""),27.0) -> 27 | B14: =IFERROR(__xludf.DUMMYFUNCTION("""COMPUTED_VALUE"""),"Student/Staff/TA/Professor") -> Student/Staff/TA/Professor | C14: =IFERROR(__xludf.DUMMYFUNCTION("""COMPUTED_VALUE"""),"view a list of my registered events") -> view a list of my registered events | D14: =IFERROR(__xludf.DUMMYFUNCTION("""COMPUTED_VALUE"""),"Upcoming and past events") -> Upcoming and past events | E14: =IFERROR(__xludf.DUMMYFUNCTION("""COMPUTED_VALUE"""),4.0) -> 4 | F14: =IFERROR(__xludf.DUMMYFUNCTION("""COMPUTED_VALUE"""),1.0) -> 1 | G14: Yehia Wael Raafat
A15: =IFERROR(__xludf.DUMMYFUNCTION("""COMPUTED_VALUE"""),31.0) -> 31 | B15: =IFERROR(__xludf.DUMMYFUNCTION("""COMPUTED_VALUE"""),"Events Office") -> Events Office | C15: =IFERROR(__xludf.DUMMYFUNCTION("""COMPUTED_VALUE"""),"create bazaars by adding the bazaar name, start and end date and time, location, short description and registration deadline") -> create bazaars by adding the bazaar name, start and end date and time, location, short description and registration deadline | E15: =IFERROR(__xludf.DUMMYFUNCTION("""COMPUTED_VALUE"""),2.0) -> 2 | F15: =IFERROR(__xludf.DUMMYFUNCTION("""COMPUTED_VALUE"""),1.0) -> 1 | G15: Ahmed Hamdy Mostafa
A16: =IFERROR(__xludf.DUMMYFUNCTION("""COMPUTED_VALUE"""),32.0) -> 32 | B16: =IFERROR(__xludf.DUMMYFUNCTION("""COMPUTED_VALUE"""),"Events Office") -> Events Office | C16: =IFERROR(__xludf.DUMMYFUNCTION("""COMPUTED_VALUE"""),"edit any of the bazaar details entered") -> edit any of the bazaar details entered | D16: =IFERROR(__xludf.DUMMYFUNCTION("""COMPUTED_VALUE"""),"Only if the bazar hasn't started yet") -> Only if the bazar hasn't started yet | E16: =IFERROR(__xludf.DUMMYFUNCTION("""COMPUTED_VALUE"""),2.0) -> 2 | F16: =IFERROR(__xludf.DUMMYFUNCTION("""COMPUTED_VALUE"""),1.0) -> 1 | G16: Ahmed Hamdy Mostafa
A17: =IFERROR(__xludf.DUMMYFUNCTION("""COMPUTED_VALUE"""),33.0) -> 33 | B17: =IFERROR(__xludf.DUMMYFUNCTION("""COMPUTED_VALUE"""),"Events Office") -> Events Office | C17: =IFERROR(__xludf.DUMMYFUNCTION("""COMPUTED_VALUE"""),"create trips by adding the trip name, location, price, start and end date and time, short description, capacity, registeration deadline") -> create trips by adding the trip name, location, price, start and end date and time, short description, capacity, registeration deadline | E17: =IFERROR(__xludf.DUMMYFUNCTION("""COMPUTED_VALUE"""),2.0) -> 2 | F17: =IFERROR(__xludf.DUMMYFUNCTION("""COMPUTED_VALUE"""),1.0) -> 1 | G17: Ahmed Hamdy Mostafa
A18: =IFERROR(__xludf.DUMMYFUNCTION("""COMPUTED_VALUE"""),34.0) -> 34 | B18: =IFERROR(__xludf.DUMMYFUNCTION("""COMPUTED_VALUE"""),"Events Office") -> Events Office | C18: =IFERROR(__xludf.DUMMYFUNCTION("""COMPUTED_VALUE"""),"edit any of the trip details") -> edit any of the trip details | D18: =IFERROR(__xludf.DUMMYFUNCTION("""COMPUTED_VALUE"""),"Only if trip start date hasn't passed yet") -> Only if trip start date hasn't passed yet | E18: =IFERROR(__xludf.DUMMYFUNCTION("""COMPUTED_VALUE"""),2.0) -> 2 | F18: =IFERROR(__xludf.DUMMYFUNCTION("""COMPUTED_VALUE"""),1.0) -> 1 | G18: Ahmed Hamdy Mostafa
A19: =IFERROR(__xludf.DUMMYFUNCTION("""COMPUTED_VALUE"""),35.0) -> 35 | B19: =IFERROR(__xludf.DUMMYFUNCTION("""COMPUTED_VALUE""")," Professor") -> Professor | C19: =IFERROR(__xludf.DUMMYFUNCTION("""COMPUTED_VALUE"""),"create workshops by adding the workshop name, location (GUC Cairo or GUC Berlin), start and end dates and times, short description, full agenda, faculty responsible (MET, IET, etc..), professor(s) participating, required budget, funding source (external o"&"r GUC), extra required resources, capacity, registeration deadline") -> create workshops by adding the workshop name, location (GUC Cairo or GUC Berlin), start and end dates and times, short description, full agenda, faculty responsible (MET, IET, etc..), professor(s) participating, required budget, funding source (external or GUC), extra required resources, capacity, registeration deadline | E19: =IFERROR(__xludf.DUMMYFUNCTION("""COMPUTED_VALUE"""),2.0) -> 2 | F19: =IFERROR(__xludf.DUMMYFUNCTION("""COMPUTED_VALUE"""),1.0) -> 1 | G19: Ahmed Mohamed Elsayed
A20: =IFERROR(__xludf.DUMMYFUNCTION("""COMPUTED_VALUE"""),36.0) -> 36 | B20: =IFERROR(__xludf.DUMMYFUNCTION("""COMPUTED_VALUE"""),"Professor") -> Professor | C20: =IFERROR(__xludf.DUMMYFUNCTION("""COMPUTED_VALUE"""),"edit any of the workshop details entered") -> edit any of the workshop details entered | E20: =IFERROR(__xludf.DUMMYFUNCTION("""COMPUTED_VALUE"""),2.0) -> 2 | F20: =IFERROR(__xludf.DUMMYFUNCTION("""COMPUTED_VALUE"""),1.0) -> 1 | G20: Ahmed Mohamed Elsayed
A21: =IFERROR(__xludf.DUMMYFUNCTION("""COMPUTED_VALUE"""),37.0) -> 37 | B21: =IFERROR(__xludf.DUMMYFUNCTION("""COMPUTED_VALUE"""),"Professor") -> Professor | C21: =IFERROR(__xludf.DUMMYFUNCTION("""COMPUTED_VALUE"""),"view a list of all workshops that i created ") -> view a list of all workshops that i created | E21: =IFERROR(__xludf.DUMMYFUNCTION("""COMPUTED_VALUE"""),2.0) -> 2 | F21: =IFERROR(__xludf.DUMMYFUNCTION("""COMPUTED_VALUE"""),1.0) -> 1 | G21: Ahmed Mohamed Elsayed
A22: =IFERROR(__xludf.DUMMYFUNCTION("""COMPUTED_VALUE"""),40.0) -> 40 | B22: =IFERROR(__xludf.DUMMYFUNCTION("""COMPUTED_VALUE"""),"Events Office") -> Events Office | C22: =IFERROR(__xludf.DUMMYFUNCTION("""COMPUTED_VALUE"""),"accept and publish workshop created by a professor ") -> accept and publish workshop created by a professor | E22: =IFERROR(__xludf.DUMMYFUNCTION("""COMPUTED_VALUE"""),2.0) -> 2 | F22: =IFERROR(__xludf.DUMMYFUNCTION("""COMPUTED_VALUE"""),1.0) -> 1 | G22: Ali Ussama Youssef
A23: =IFERROR(__xludf.DUMMYFUNCTION("""COMPUTED_VALUE"""),41.0) -> 41 | B23: =IFERROR(__xludf.DUMMYFUNCTION("""COMPUTED_VALUE"""),"Events Office") -> Events Office | C23: =IFERROR(__xludf.DUMMYFUNCTION("""COMPUTED_VALUE"""),"reject workshop ") -> reject workshop | E23: =IFERROR(__xludf.DUMMYFUNCTION("""COMPUTED_VALUE"""),2.0) -> 2 | F23: =IFERROR(__xludf.DUMMYFUNCTION("""COMPUTED_VALUE"""),1.0) -> 1 | G23: Ali Ussama Youssef
A24: =IFERROR(__xludf.DUMMYFUNCTION("""COMPUTED_VALUE"""),42.0) -> 42 | B24: =IFERROR(__xludf.DUMMYFUNCTION("""COMPUTED_VALUE"""),"Events Office") -> Events Office | C24: =IFERROR(__xludf.DUMMYFUNCTION("""COMPUTED_VALUE"""),"request edits in workshop details") -> request edits in workshop details | E24: =IFERROR(__xludf.DUMMYFUNCTION("""COMPUTED_VALUE"""),2.0) -> 2 | F24: =IFERROR(__xludf.DUMMYFUNCTION("""COMPUTED_VALUE"""),1.0) -> 1 | G24: Ali Ussama Youssef
A25: =IFERROR(__xludf.DUMMYFUNCTION("""COMPUTED_VALUE"""),45.0) -> 45 | B25: =IFERROR(__xludf.DUMMYFUNCTION("""COMPUTED_VALUE"""),"Events Office") -> Events Office | C25: =IFERROR(__xludf.DUMMYFUNCTION("""COMPUTED_VALUE"""),"create conferences by adding the conference name, start and end dates and times, short description, full agenda, conference website link, required budget, source of funding (extrernal or GUC), extra required resources") -> create conferences by adding the conference name, start and end dates and times, short description, full agenda, conference website link, required budget, source of funding (extrernal or GUC), extra required resources | D25: =IFERROR(__xludf.DUMMYFUNCTION("""COMPUTED_VALUE"""),"the conference website will contain all the conference's details. Each conference usually has a landing page so there will be no need to add ALL the info to the event on the system") -> the conference website will contain all the conference's details. Each conference usually has a landing page so there will be no need to add ALL the info to the event on the system | E25: =IFERROR(__xludf.DUMMYFUNCTION("""COMPUTED_VALUE"""),2.0) -> 2 | F25: =IFERROR(__xludf.DUMMYFUNCTION("""COMPUTED_VALUE"""),1.0) -> 1 | G25: Ahmed Hamdy Mostafa
A26: =IFERROR(__xludf.DUMMYFUNCTION("""COMPUTED_VALUE"""),46.0) -> 46 | B26: =IFERROR(__xludf.DUMMYFUNCTION("""COMPUTED_VALUE"""),"Events Office") -> Events Office | C26: =IFERROR(__xludf.DUMMYFUNCTION("""COMPUTED_VALUE"""),"edit any of the conference details") -> edit any of the conference details | E26: =IFERROR(__xludf.DUMMYFUNCTION("""COMPUTED_VALUE"""),2.0) -> 2 | F26: =IFERROR(__xludf.DUMMYFUNCTION("""COMPUTED_VALUE"""),1.0) -> 1 | G26: Ahmed Hamdy Mostafa
A27: =IFERROR(__xludf.DUMMYFUNCTION("""COMPUTED_VALUE"""),48.0) -> 48 | B27: =IFERROR(__xludf.DUMMYFUNCTION("""COMPUTED_VALUE"""),"Events Office/Admin") -> Events Office/Admin | C27: =IFERROR(__xludf.DUMMYFUNCTION("""COMPUTED_VALUE"""),"delete any event") -> delete any event | D27: =IFERROR(__xludf.DUMMYFUNCTION("""COMPUTED_VALUE"""),"if no one registered for it yet") -> if no one registered for it yet | E27: =IFERROR(__xludf.DUMMYFUNCTION("""COMPUTED_VALUE"""),2.0) -> 2 | F27: =IFERROR(__xludf.DUMMYFUNCTION("""COMPUTED_VALUE"""),1.0) -> 1 | G27: Abdelhamid Sameh Abdelhamid
A28: =IFERROR(__xludf.DUMMYFUNCTION("""COMPUTED_VALUE"""),59.0) -> 59 | B28: =IFERROR(__xludf.DUMMYFUNCTION("""COMPUTED_VALUE"""),"Vendor") -> Vendor | C28: =IFERROR(__xludf.DUMMYFUNCTION("""COMPUTED_VALUE"""),"view a list of upcoming bazaars ") -> view a list of upcoming bazaars | E28: =IFERROR(__xludf.DUMMYFUNCTION("""COMPUTED_VALUE"""),2.0) -> 2 | F28: =IFERROR(__xludf.DUMMYFUNCTION("""COMPUTED_VALUE"""),1.0) -> 1 | G28: Ahmed Khalid Mohamed
A29: =IFERROR(__xludf.DUMMYFUNCTION("""COMPUTED_VALUE"""),60.0) -> 60 | B29: =IFERROR(__xludf.DUMMYFUNCTION("""COMPUTED_VALUE"""),"Vendor") -> Vendor | C29: =IFERROR(__xludf.DUMMYFUNCTION("""COMPUTED_VALUE"""),"apply to join a bazaar from the list of bazaars by filling in a form with the following details: names and emails of a max of 5 individuals attending, booth size ") -> apply to join a bazaar from the list of bazaars by filling in a form with the following details: names and emails of a max of 5 individuals attending, booth size | D29: =IFERROR(__xludf.DUMMYFUNCTION("""COMPUTED_VALUE"""),"booth size can be 2x2 or 4x4") -> booth size can be 2x2 or 4x4 | E29: =IFERROR(__xludf.DUMMYFUNCTION("""COMPUTED_VALUE"""),2.0) -> 2 | F29: =IFERROR(__xludf.DUMMYFUNCTION("""COMPUTED_VALUE"""),1.0) -> 1 | G29: Ahmed Khalid Mohamed
A30: =IFERROR(__xludf.DUMMYFUNCTION("""COMPUTED_VALUE"""),61.0) -> 61 | B30: =IFERROR(__xludf.DUMMYFUNCTION("""COMPUTED_VALUE"""),"Vendor") -> Vendor | C30: =IFERROR(__xludf.DUMMYFUNCTION("""COMPUTED_VALUE"""),"apply for a booth in platform by filling in a form with the following details: names and emails of a max of 5 individuals attending, duration of booth set up, location of booth setup, booth size ") -> apply for a booth in platform by filling in a form with the following details: names and emails of a max of 5 individuals attending, duration of booth set up, location of booth setup, booth size | D30: =IFERROR(__xludf.DUMMYFUNCTION("""COMPUTED_VALUE"""),"duration can be 1 week - 4 weeks and location in platform will be selected according to a map of the platform and booth size can be 2x2 or 4x4") -> duration can be 1 week - 4 weeks and location in platform will be selected according to a map of the platform and booth size can be 2x2 or 4x4 | E30: =IFERROR(__xludf.DUMMYFUNCTION("""COMPUTED_VALUE"""),2.0) -> 2 | F30: =IFERROR(__xludf.DUMMYFUNCTION("""COMPUTED_VALUE"""),1.0) -> 1 | G30: Ahmed Khalid Mohamed
A31: =IFERROR(__xludf.DUMMYFUNCTION("""COMPUTED_VALUE"""),68.0) -> 68 | B31: =IFERROR(__xludf.DUMMYFUNCTION("""COMPUTED_VALUE"""),"Vendor") -> Vendor | C31: =IFERROR(__xludf.DUMMYFUNCTION("""COMPUTED_VALUE"""),"view all upcoming bazaars or booth set ups I am participating in (accepted requests only)") -> view all upcoming bazaars or booth set ups I am participating in (accepted requests only) | E31: =IFERROR(__xludf.DUMMYFUNCTION("""COMPUTED_VALUE"""),2.0) -> 2 | F31: =IFERROR(__xludf.DUMMYFUNCTION("""COMPUTED_VALUE"""),1.0) -> 1 | G31: Ahmed Khalid Mohamed
A32: =IFERROR(__xludf.DUMMYFUNCTION("""COMPUTED_VALUE"""),69.0) -> 69 | B32: =IFERROR(__xludf.DUMMYFUNCTION("""COMPUTED_VALUE"""),"Vendor") -> Vendor | C32: =IFERROR(__xludf.DUMMYFUNCTION("""COMPUTED_VALUE"""),"view all requests for upcoming bazaars or booth set ups I want to participate in (pending or rejected)") -> view all requests for upcoming bazaars or booth set ups I want to participate in (pending or rejected) | E32: =IFERROR(__xludf.DUMMYFUNCTION("""COMPUTED_VALUE"""),2.0) -> 2 | F32: =IFERROR(__xludf.DUMMYFUNCTION("""COMPUTED_VALUE"""),1.0) -> 1 | G32: Ahmed Khalid Mohamed
A33: =IFERROR(__xludf.DUMMYFUNCTION("""COMPUTED_VALUE"""),75.0) -> 75 | B33: =IFERROR(__xludf.DUMMYFUNCTION("""COMPUTED_VALUE"""),"Events Office/Admin") -> Events Office/Admin | C33: =IFERROR(__xludf.DUMMYFUNCTION("""COMPUTED_VALUE"""),"view the details of vendor participation requests in bazaars or booths") -> view the details of vendor participation requests in bazaars or booths | E33: =IFERROR(__xludf.DUMMYFUNCTION("""COMPUTED_VALUE"""),2.0) -> 2 | F33: =IFERROR(__xludf.DUMMYFUNCTION("""COMPUTED_VALUE"""),1.0) -> 1 | G33: Abdelhamid Sameh Abdelhamid
A34: =IFERROR(__xludf.DUMMYFUNCTION("""COMPUTED_VALUE"""),77.0) -> 77 | B34: =IFERROR(__xludf.DUMMYFUNCTION("""COMPUTED_VALUE"""),"Events Office/Admin") -> Events Office/Admin | C34: =IFERROR(__xludf.DUMMYFUNCTION("""COMPUTED_VALUE"""),"accept /reject vendors participation requests") -> accept /reject vendors participation requests | E34: =IFERROR(__xludf.DUMMYFUNCTION("""COMPUTED_VALUE"""),2.0) -> 2 | F34: =IFERROR(__xludf.DUMMYFUNCTION("""COMPUTED_VALUE"""),1.0) -> 1 | G34: Abdelhamid Sameh Abdelhamid
A35: =IFERROR(__xludf.DUMMYFUNCTION("""COMPUTED_VALUE"""),78.0) -> 78 | B35: =IFERROR(__xludf.DUMMYFUNCTION("""COMPUTED_VALUE"""),"Student") -> Student | C35: =IFERROR(__xludf.DUMMYFUNCTION("""COMPUTED_VALUE"""),"view all the courts on campus (basketball/tennis/football) and their availability dates and times") -> view all the courts on campus (basketball/tennis/football) and their availability dates and times | E35: =IFERROR(__xludf.DUMMYFUNCTION("""COMPUTED_VALUE"""),2.0) -> 2 | F35: =IFERROR(__xludf.DUMMYFUNCTION("""COMPUTED_VALUE"""),1.0) -> 1 | G35: Ahmed Khalid Mohamed
A36: =IFERROR(__xludf.DUMMYFUNCTION("""COMPUTED_VALUE"""),80.0) -> 80 | B36: =IFERROR(__xludf.DUMMYFUNCTION("""COMPUTED_VALUE"""),"Student/Staff/ Events Office/TA/ Professor") -> Student/Staff/ Events Office/TA/ Professor | C36: =IFERROR(__xludf.DUMMYFUNCTION("""COMPUTED_VALUE"""),"view the gym schedule for each month's sessions (e.g. yoga, pilates, aerobics, Zumba, cross circuit, kick-boxing)") -> view the gym schedule for each month's sessions (e.g. yoga, pilates, aerobics, Zumba, cross circuit, kick-boxing) | E36: =IFERROR(__xludf.DUMMYFUNCTION("""COMPUTED_VALUE"""),2.5) -> 2.5 | F36: =IFERROR(__xludf.DUMMYFUNCTION("""COMPUTED_VALUE"""),1.0) -> 1 | G36: Ahmed Khalid Mohamed
A37: =IFERROR(__xludf.DUMMYFUNCTION("""COMPUTED_VALUE"""),84.0) -> 84 | B37: =IFERROR(__xludf.DUMMYFUNCTION("""COMPUTED_VALUE"""),"Events Office") -> Events Office | C37: =IFERROR(__xludf.DUMMYFUNCTION("""COMPUTED_VALUE"""),"create a gym session with the following details: date, time, duration, type (e.g. yoga, pilates, aerobics, Zumba, cross circuit, kick-boxing), max number of participants") -> create a gym session with the following details: date, time, duration, type (e.g. yoga, pilates, aerobics, Zumba, cross circuit, kick-boxing), max number of participants | E37: =IFERROR(__xludf.DUMMYFUNCTION("""COMPUTED_VALUE"""),2.0) -> 2 | F37: =IFERROR(__xludf.DUMMYFUNCTION("""COMPUTED_VALUE"""),1.0) -> 1 | G37: Ahmed Khalid Mohamed

Sheet Sprint 2
B1: As a | C1: I should be able to | D1: Comment | E1: Marks | F1: Sprint | G1: who | H1: done
A2: =IFERROR(__xludf.DUMMYFUNCTION("IFERROR(FILTER('Functional Requirements'!A:F, 'Functional Requirements'!F:F=2), ""No Sprint 2 items"") "),3.0) -> 3 | B2: =IFERROR(__xludf.DUMMYFUNCTION("""COMPUTED_VALUE"""),"Vendor") -> Vendor | C2: =IFERROR(__xludf.DUMMYFUNCTION("""COMPUTED_VALUE"""),"upload tax card and logo to prove company validity") -> upload tax card and logo to prove company validity | E2: =IFERROR(__xludf.DUMMYFUNCTION("""COMPUTED_VALUE"""),2.0) -> 2 | F2: =IFERROR(__xludf.DUMMYFUNCTION("""COMPUTED_VALUE"""),2.0) -> 2 | G2: Ali Ussama Youssef
A3: =IFERROR(__xludf.DUMMYFUNCTION("""COMPUTED_VALUE"""),4.0) -> 4 | B3: =IFERROR(__xludf.DUMMYFUNCTION("""COMPUTED_VALUE"""),"Student") -> Student | C3: =IFERROR(__xludf.DUMMYFUNCTION("""COMPUTED_VALUE"""),"receive a verification email after registration ") -> receive a verification email after registration | D3: =IFERROR(__xludf.DUMMYFUNCTION("""COMPUTED_VALUE"""),"The verification mail should contain a verification link that automatically redirects me to the login page If I didnot click on the link I shouldnt be verified hence the login should fail") -> The verification mail should contain a verification link that automatically redirects me to the login page If I didnot click on the link I shouldnt be verified hence the login should fail | E3: =IFERROR(__xludf.DUMMYFUNCTION("""COMPUTED_VALUE"""),2.0) -> 2 | F3: =IFERROR(__xludf.DUMMYFUNCTION("""COMPUTED_VALUE"""),2.0) -> 2 | G3: Ali Ussama Youssef
A4: =IFERROR(__xludf.DUMMYFUNCTION("""COMPUTED_VALUE"""),13.0) -> 13 | B4: =IFERROR(__xludf.DUMMYFUNCTION("""COMPUTED_VALUE"""),"Student/Staff/ Events Office/TA/ Professor/ Admin") -> Student/Staff/ Events Office/TA/ Professor/ Admin | C4: =IFERROR(__xludf.DUMMYFUNCTION("""COMPUTED_VALUE"""),"filter the events by a specific name(Professor name incase of a workshop or a conference), location, type or date") -> filter the events by a specific name(Professor name incase of a workshop or a conference), location, type or date | E4: =IFERROR(__xludf.DUMMYFUNCTION("""COMPUTED_VALUE"""),3.0) -> 3 | F4: =IFERROR(__xludf.DUMMYFUNCTION("""COMPUTED_VALUE"""),2.0) -> 2 | G4: Yehia Wael Raafat
A5: =IFERROR(__xludf.DUMMYFUNCTION("""COMPUTED_VALUE"""),14.0) -> 14 | B5: =IFERROR(__xludf.DUMMYFUNCTION("""COMPUTED_VALUE"""),"Student/Staff/ Events Office/TA/ Professor/ Admin") -> Student/Staff/ Events Office/TA/ Professor/ Admin | C5: =IFERROR(__xludf.DUMMYFUNCTION("""COMPUTED_VALUE"""),"sort the events by date") -> sort the events by date | E5: =IFERROR(__xludf.DUMMYFUNCTION("""COMPUTED_VALUE"""),3.0) -> 3 | F5: =IFERROR(__xludf.DUMMYFUNCTION("""COMPUTED_VALUE"""),2.0) -> 2 | G5: Yehia Wael Raafat
A6: =IFERROR(__xludf.DUMMYFUNCTION("""COMPUTED_VALUE"""),15.0) -> 15 | B6: =IFERROR(__xludf.DUMMYFUNCTION("""COMPUTED_VALUE"""),"Student/Staff/ TA/ Professor") -> Student/Staff/ TA/ Professor | C6: =IFERROR(__xludf.DUMMYFUNCTION("""COMPUTED_VALUE"""),"rate an event that i attended ") -> rate an event that i attended | E6: =IFERROR(__xludf.DUMMYFUNCTION("""COMPUTED_VALUE"""),2.0) -> 2 | F6: =IFERROR(__xludf.DUMMYFUNCTION("""COMPUTED_VALUE"""),2.0) -> 2
A7: =IFERROR(__xludf.DUMMYFUNCTION("""COMPUTED_VALUE"""),16.0) -> 16 | B7: =IFERROR(__xludf.DUMMYFUNCTION("""COMPUTED_VALUE"""),"Student/Staff/TA/ Professor") -> Student/Staff/TA/ Professor | C7: =IFERROR(__xludf.DUMMYFUNCTION("""COMPUTED_VALUE"""),"comment on an event that i attended") -> comment on an event that i attended | E7: =IFERROR(__xludf.DUMMYFUNCTION("""COMPUTED_VALUE"""),2.0) -> 2 | F7: =IFERROR(__xludf.DUMMYFUNCTION("""COMPUTED_VALUE"""),2.0) -> 2
A8: =IFERROR(__xludf.DUMMYFUNCTION("""COMPUTED_VALUE"""),17.0) -> 17 | B8: =IFERROR(__xludf.DUMMYFUNCTION("""COMPUTED_VALUE"""),"Student/Staff/ Events Office/TA/ Professor/ Admin") -> Student/Staff/ Events Office/TA/ Professor/ Admin | C8: =IFERROR(__xludf.DUMMYFUNCTION("""COMPUTED_VALUE"""),"view all ratings and comments on any event") -> view all ratings and comments on any event | E8: =IFERROR(__xludf.DUMMYFUNCTION("""COMPUTED_VALUE"""),3.0) -> 3 | F8: =IFERROR(__xludf.DUMMYFUNCTION("""COMPUTED_VALUE"""),2.0) -> 2
A9: =IFERROR(__xludf.DUMMYFUNCTION("""COMPUTED_VALUE"""),18.0) -> 18 | B9: =IFERROR(__xludf.DUMMYFUNCTION("""COMPUTED_VALUE"""),"Admin") -> Admin | C9: =IFERROR(__xludf.DUMMYFUNCTION("""COMPUTED_VALUE"""),"delete any inappropriate comments") -> delete any inappropriate comments | E9: =IFERROR(__xludf.DUMMYFUNCTION("""COMPUTED_VALUE"""),2.0) -> 2 | F9: =IFERROR(__xludf.DUMMYFUNCTION("""COMPUTED_VALUE"""),2.0) -> 2
A10: =IFERROR(__xludf.DUMMYFUNCTION("""COMPUTED_VALUE"""),19.0) -> 19 | B10: =IFERROR(__xludf.DUMMYFUNCTION("""COMPUTED_VALUE"""),"Admin") -> Admin | C10: =IFERROR(__xludf.DUMMYFUNCTION("""COMPUTED_VALUE"""),"block any user") -> block any user | E10: =IFERROR(__xludf.DUMMYFUNCTION("""COMPUTED_VALUE"""),2.0) -> 2 | F10: =IFERROR(__xludf.DUMMYFUNCTION("""COMPUTED_VALUE"""),2.0) -> 2
A11: =IFERROR(__xludf.DUMMYFUNCTION("""COMPUTED_VALUE"""),21.0) -> 21 | B11: =IFERROR(__xludf.DUMMYFUNCTION("""COMPUTED_VALUE"""),"Student/Staff/ Events Office/TA/ Professor") -> Student/Staff/ Events Office/TA/ Professor | C11: =IFERROR(__xludf.DUMMYFUNCTION("""COMPUTED_VALUE"""),"receive a warning email if any of my comments were deleted for being inappropriate") -> receive a warning email if any of my comments were deleted for being inappropriate | E11: =IFERROR(__xludf.DUMMYFUNCTION("""COMPUTED_VALUE"""),5.0) -> 5 | F11: =IFERROR(__xludf.DUMMYFUNCTION("""COMPUTED_VALUE"""),2.0) -> 2
A12: =IFERROR(__xludf.DUMMYFUNCTION("""COMPUTED_VALUE"""),22.0) -> 22 | B12: =IFERROR(__xludf.DUMMYFUNCTION("""COMPUTED_VALUE"""),"Student/Staff/TA/Professor") -> Student/Staff/TA/Professor | C12: =IFERROR(__xludf.DUMMYFUNCTION("""COMPUTED_VALUE"""),"add an event to their favorites list") -> add an event to their favorites list | E12: =IFERROR(__xludf.DUMMYFUNCTION("""COMPUTED_VALUE"""),4.0) -> 4 | F12: =IFERROR(__xludf.DUMMYFUNCTION("""COMPUTED_VALUE"""),2.0) -> 2
A13: =IFERROR(__xludf.DUMMYFUNCTION("""COMPUTED_VALUE"""),23.0) -> 23 | B13: =IFERROR(__xludf.DUMMYFUNCTION("""COMPUTED_VALUE"""),"Student/Staff/TA/Professor") -> Student/Staff/TA/Professor | C13: =IFERROR(__xludf.DUMMYFUNCTION("""COMPUTED_VALUE"""),"view my favorites list") -> view my favorites list | E13: =IFERROR(__xludf.DUMMYFUNCTION("""COMPUTED_VALUE"""),4.0) -> 4 | F13: =IFERROR(__xludf.DUMMYFUNCTION("""COMPUTED_VALUE"""),2.0) -> 2
A14: =IFERROR(__xludf.DUMMYFUNCTION("""COMPUTED_VALUE"""),25.0) -> 25 | B14: =IFERROR(__xludf.DUMMYFUNCTION("""COMPUTED_VALUE"""),"Student/Staff/TA/Professor") -> Student/Staff/TA/Professor | C14: =IFERROR(__xludf.DUMMYFUNCTION("""COMPUTED_VALUE"""),"pay for the workshop/trip he/she registered for using credit card/ debit card (using Stripe) or from wallet if available") -> pay for the workshop/trip he/she registered for using credit card/ debit card (using Stripe) or from wallet if available | E14: =IFERROR(__xludf.DUMMYFUNCTION("""COMPUTED_VALUE"""),4.0) -> 4 | F14: =IFERROR(__xludf.DUMMYFUNCTION("""COMPUTED_VALUE"""),2.0) -> 2
A15: =IFERROR(__xludf.DUMMYFUNCTION("""COMPUTED_VALUE"""),26.0) -> 26 | B15: =IFERROR(__xludf.DUMMYFUNCTION("""COMPUTED_VALUE"""),"Student/Staff/TA/Professor") -> Student/Staff/TA/Professor | C15: =IFERROR(__xludf.DUMMYFUNCTION("""COMPUTED_VALUE"""),"receive a payment receipt via email upon paying") -> receive a payment receipt via email upon paying | E15: =IFERROR(__xludf.DUMMYFUNCTION("""COMPUTED_VALUE"""),4.0) -> 4 | F15: =IFERROR(__xludf.DUMMYFUNCTION("""COMPUTED_VALUE"""),2.0) -> 2
A16: =IFERROR(__xludf.DUMMYFUNCTION("""COMPUTED_VALUE"""),28.0) -> 28 | B16: =IFERROR(__xludf.DUMMYFUNCTION("""COMPUTED_VALUE"""),"Student/Staff/TA/Professor") -> Student/Staff/TA/Professor | C16: =IFERROR(__xludf.DUMMYFUNCTION("""COMPUTED_VALUE"""),"cancel the registration and refund the amount paid on my wallet") -> cancel the registration and refund the amount paid on my wallet | D16: =IFERROR(__xludf.DUMMYFUNCTION("""COMPUTED_VALUE"""),"cancellation can only be accepted if there are still 2 weeks for the event") -> cancellation can only be accepted if there are still 2 weeks for the event | E16: =IFERROR(__xludf.DUMMYFUNCTION("""COMPUTED_VALUE"""),4.0) -> 4 | F16: =IFERROR(__xludf.DUMMYFUNCTION("""COMPUTED_VALUE"""),2.0) -> 2
A17: =IFERROR(__xludf.DUMMYFUNCTION("""COMPUTED_VALUE"""),29.0) -> 29 | B17: =IFERROR(__xludf.DUMMYFUNCTION("""COMPUTED_VALUE"""),"Student/Staff/TA/Professor") -> Student/Staff/TA/Professor | C17: =IFERROR(__xludf.DUMMYFUNCTION("""COMPUTED_VALUE"""),"view amount refunded in my wallet") -> view amount refunded in my wallet | E17: =IFERROR(__xludf.DUMMYFUNCTION("""COMPUTED_VALUE"""),4.0) -> 4 | F17: =IFERROR(__xludf.DUMMYFUNCTION("""COMPUTED_VALUE"""),2.0) -> 2
A18: =IFERROR(__xludf.DUMMYFUNCTION("""COMPUTED_VALUE"""),30.0) -> 30 | B18: =IFERROR(__xludf.DUMMYFUNCTION("""COMPUTED_VALUE"""),"Student/Staff/TA/Professor") -> Student/Staff/TA/Professor | C18: =IFERROR(__xludf.DUMMYFUNCTION("""COMPUTED_VALUE"""),"receive a certificate of attendance upon finishing workshop via email") -> receive a certificate of attendance upon finishing workshop via email | E18: =IFERROR(__xludf.DUMMYFUNCTION("""COMPUTED_VALUE"""),4.0) -> 4 | F18: =IFERROR(__xludf.DUMMYFUNCTION("""COMPUTED_VALUE"""),2.0) -> 2
A19: =IFERROR(__xludf.DUMMYFUNCTION("""COMPUTED_VALUE"""),38.0) -> 38 | B19: =IFERROR(__xludf.DUMMYFUNCTION("""COMPUTED_VALUE"""),"Professor") -> Professor | C19: =IFERROR(__xludf.DUMMYFUNCTION("""COMPUTED_VALUE"""),"view a list of participants in a workshop that i created and the number of remaining spots") -> view a list of participants in a workshop that i created and the number of remaining spots | E19: =IFERROR(__xludf.DUMMYFUNCTION("""COMPUTED_VALUE"""),2.0) -> 2 | F19: =IFERROR(__xludf.DUMMYFUNCTION("""COMPUTED_VALUE"""),2.0) -> 2
A20: =IFERROR(__xludf.DUMMYFUNCTION("""COMPUTED_VALUE"""),39.0) -> 39 | B20: =IFERROR(__xludf.DUMMYFUNCTION("""COMPUTED_VALUE"""),"Events Office") -> Events Office | C20: =IFERROR(__xludf.DUMMYFUNCTION("""COMPUTED_VALUE"""),"receive notifications on the system when doctors submit workshop requests") -> receive notifications on the system when doctors submit workshop requests | E20: =IFERROR(__xludf.DUMMYFUNCTION("""COMPUTED_VALUE"""),2.0) -> 2 | F20: =IFERROR(__xludf.DUMMYFUNCTION("""COMPUTED_VALUE"""),2.0) -> 2
A21: =IFERROR(__xludf.DUMMYFUNCTION("""COMPUTED_VALUE"""),43.0) -> 43 | B21: =IFERROR(__xludf.DUMMYFUNCTION("""COMPUTED_VALUE"""),"Professor") -> Professor | C21: =IFERROR(__xludf.DUMMYFUNCTION("""COMPUTED_VALUE"""),"view status and any requested edits of my submitted workshops") -> view status and any requested edits of my submitted workshops | E21: =IFERROR(__xludf.DUMMYFUNCTION("""COMPUTED_VALUE"""),2.0) -> 2 | F21: =IFERROR(__xludf.DUMMYFUNCTION("""COMPUTED_VALUE"""),2.0) -> 2
A22: =IFERROR(__xludf.DUMMYFUNCTION("""COMPUTED_VALUE"""),44.0) -> 44 | B22: =IFERROR(__xludf.DUMMYFUNCTION("""COMPUTED_VALUE"""),"Professor") -> Professor | C22: =IFERROR(__xludf.DUMMYFUNCTION("""COMPUTED_VALUE"""),"receive a notification on the system if my workshop has been accepted/rejected") -> receive a notification on the system if my workshop has been accepted/rejected | E22: =IFERROR(__xludf.DUMMYFUNCTION("""COMPUTED_VALUE"""),2.0) -> 2 | F22: =IFERROR(__xludf.DUMMYFUNCTION("""COMPUTED_VALUE"""),2.0) -> 2
A23: =IFERROR(__xludf.DUMMYFUNCTION("""COMPUTED_VALUE"""),47.0) -> 47 | B23: =IFERROR(__xludf.DUMMYFUNCTION("""COMPUTED_VALUE"""),"Events Office") -> Events Office | C23: =IFERROR(__xludf.DUMMYFUNCTION("""COMPUTED_VALUE"""),"archive events that have already passed") -> archive events that have already passed | D23: =IFERROR(__xludf.DUMMYFUNCTION("""COMPUTED_VALUE"""),"this applies to ALL kinds of events on the system") -> this applies to ALL kinds of events on the system | E23: =IFERROR(__xludf.DUMMYFUNCTION("""COMPUTED_VALUE"""),2.0) -> 2 | F23: =IFERROR(__xludf.DUMMYFUNCTION("""COMPUTED_VALUE"""),2.0) -> 2
A24: =IFERROR(__xludf.DUMMYFUNCTION("""COMPUTED_VALUE"""),49.0) -> 49 | B24: =IFERROR(__xludf.DUMMYFUNCTION("""COMPUTED_VALUE"""),"Events Office ") -> Events Office | C24: =IFERROR(__xludf.DUMMYFUNCTION("""COMPUTED_VALUE"""),"export names of those registered for any event (except conferences) in a .xlxs sheet") -> export names of those registered for any event (except conferences) in a .xlxs sheet | E24: =IFERROR(__xludf.DUMMYFUNCTION("""COMPUTED_VALUE"""),2.0) -> 2 | F24: =IFERROR(__xludf.DUMMYFUNCTION("""COMPUTED_VALUE"""),2.0) -> 2
A25: =IFERROR(__xludf.DUMMYFUNCTION("""COMPUTED_VALUE"""),50.0) -> 50 | B25: =IFERROR(__xludf.DUMMYFUNCTION("""COMPUTED_VALUE"""),"Events Office") -> Events Office | C25: =IFERROR(__xludf.DUMMYFUNCTION("""COMPUTED_VALUE"""),"restrict events to specific users") -> restrict events to specific users | D25: =IFERROR(__xludf.DUMMYFUNCTION("""COMPUTED_VALUE"""),"means i can choose if this workshop is only available for students for example") -> means i can choose if this workshop is only available for students for example | E25: =IFERROR(__xludf.DUMMYFUNCTION("""COMPUTED_VALUE"""),2.0) -> 2 | F25: =IFERROR(__xludf.DUMMYFUNCTION("""COMPUTED_VALUE"""),2.0) -> 2
A26: =IFERROR(__xludf.DUMMYFUNCTION("""COMPUTED_VALUE"""),51.0) -> 51 | B26: =IFERROR(__xludf.DUMMYFUNCTION("""COMPUTED_VALUE"""),"Events Office") -> Events Office | C26: =IFERROR(__xludf.DUMMYFUNCTION("""COMPUTED_VALUE"""),"generate QR codes for external visitors to bazaars and career fairs") -> generate QR codes for external visitors to bazaars and career fairs | E26: =IFERROR(__xludf.DUMMYFUNCTION("""COMPUTED_VALUE"""),2.0) -> 2 | F26: =IFERROR(__xludf.DUMMYFUNCTION("""COMPUTED_VALUE"""),2.0) -> 2
A27: =IFERROR(__xludf.DUMMYFUNCTION("""COMPUTED_VALUE"""),52.0) -> 52 | B27: =IFERROR(__xludf.DUMMYFUNCTION("""COMPUTED_VALUE"""),"Events Office/Admin") -> Events Office/Admin | C27: =IFERROR(__xludf.DUMMYFUNCTION("""COMPUTED_VALUE"""),"view a report containing the total number of attendees in events ") -> view a report containing the total number of attendees in events | E27: =IFERROR(__xludf.DUMMYFUNCTION("""COMPUTED_VALUE"""),2.0) -> 2 | F27: =IFERROR(__xludf.DUMMYFUNCTION("""COMPUTED_VALUE"""),2.0) -> 2
A28: =IFERROR(__xludf.DUMMYFUNCTION("""COMPUTED_VALUE"""),53.0) -> 53 | B28: =IFERROR(__xludf.DUMMYFUNCTION("""COMPUTED_VALUE"""),"Events Office/Admin") -> Events Office/Admin | C28: =IFERROR(__xludf.DUMMYFUNCTION("""COMPUTED_VALUE"""),"filter the report of total number of attendees in events by event name/event type/date") -> filter the report of total number of attendees in events by event name/event type/date | E28: =IFERROR(__xludf.DUMMYFUNCTION("""COMPUTED_VALUE"""),2.0) -> 2 | F28: =IFERROR(__xludf.DUMMYFUNCTION("""COMPUTED_VALUE"""),2.0) -> 2
A29: =IFERROR(__xludf.DUMMYFUNCTION("""COMPUTED_VALUE"""),54.0) -> 54 | B29: =IFERROR(__xludf.DUMMYFUNCTION("""COMPUTED_VALUE"""),"Events Office/Admin") -> Events Office/Admin | C29: =IFERROR(__xludf.DUMMYFUNCTION("""COMPUTED_VALUE"""),"view a sales report containing all the revenue from different events") -> view a sales report containing all the revenue from different events | E29: =IFERROR(__xludf.DUMMYFUNCTION("""COMPUTED_VALUE"""),2.0) -> 2 | F29: =IFERROR(__xludf.DUMMYFUNCTION("""COMPUTED_VALUE"""),2.0) -> 2
A30: =IFERROR(__xludf.DUMMYFUNCTION("""COMPUTED_VALUE"""),55.0) -> 55 | B30: =IFERROR(__xludf.DUMMYFUNCTION("""COMPUTED_VALUE"""),"Events Office/Admin") -> Events Office/Admin | C30: =IFERROR(__xludf.DUMMYFUNCTION("""COMPUTED_VALUE"""),"filter sales report based on event type and/or date") -> filter sales report based on event type and/or date | E30: =IFERROR(__xludf.DUMMYFUNCTION("""COMPUTED_VALUE"""),2.0) -> 2 | F30: =IFERROR(__xludf.DUMMYFUNCTION("""COMPUTED_VALUE"""),2.0) -> 2
A31: =IFERROR(__xludf.DUMMYFUNCTION("""COMPUTED_VALUE"""),56.0) -> 56 | B31: =IFERROR(__xludf.DUMMYFUNCTION("""COMPUTED_VALUE"""),"Events Office/Admin") -> Events Office/Admin | C31: =IFERROR(__xludf.DUMMYFUNCTION("""COMPUTED_VALUE"""),"sort sales report by revenue (least to greatest or greatest to least)") -> sort sales report by revenue (least to greatest or greatest to least) | E31: =IFERROR(__xludf.DUMMYFUNCTION("""COMPUTED_VALUE"""),2.0) -> 2 | F31: =IFERROR(__xludf.DUMMYFUNCTION("""COMPUTED_VALUE"""),2.0) -> 2
A32: =IFERROR(__xludf.DUMMYFUNCTION("""COMPUTED_VALUE"""),57.0) -> 57 | B32: =IFERROR(__xludf.DUMMYFUNCTION("""COMPUTED_VALUE"""),"Student/Staff/ Events Office/TA/ Professor") -> Student/Staff/ Events Office/TA/ Professor | C32: =IFERROR(__xludf.DUMMYFUNCTION("""COMPUTED_VALUE"""),"receive notifications on the system for any new added events") -> receive notifications on the system for any new added events | E32: =IFERROR(__xludf.DUMMYFUNCTION("""COMPUTED_VALUE"""),5.0) -> 5 | F32: =IFERROR(__xludf.DUMMYFUNCTION("""COMPUTED_VALUE"""),2.0) -> 2
A33: =IFERROR(__xludf.DUMMYFUNCTION("""COMPUTED_VALUE"""),58.0) -> 58 | B33: =IFERROR(__xludf.DUMMYFUNCTION("""COMPUTED_VALUE"""),"Student/Staff/ Events Office/TA/ Professor") -> Student/Staff/ Events Office/TA/ Professor | C33: =IFERROR(__xludf.DUMMYFUNCTION("""COMPUTED_VALUE"""),"receive reminders as notifications on the system for any events i registered for 1 day and 1 hour prior") -> receive reminders as notifications on the system for any events i registered for 1 day and 1 hour prior | E33: =IFERROR(__xludf.DUMMYFUNCTION("""COMPUTED_VALUE"""),5.0) -> 5 | F33: =IFERROR(__xludf.DUMMYFUNCTION("""COMPUTED_VALUE"""),2.0) -> 2
A34: =IFERROR(__xludf.DUMMYFUNCTION("""COMPUTED_VALUE"""),62.0) -> 62 | B34: =IFERROR(__xludf.DUMMYFUNCTION("""COMPUTED_VALUE"""),"Vendor") -> Vendor | C34: =IFERROR(__xludf.DUMMYFUNCTION("""COMPUTED_VALUE"""),"upload IDs of individuals attending for the entire duration of bazaar or booth set up in platform") -> upload IDs of individuals attending for the entire duration of bazaar or booth set up in platform | E34: =IFERROR(__xludf.DUMMYFUNCTION("""COMPUTED_VALUE"""),2.0) -> 2 | F34: =IFERROR(__xludf.DUMMYFUNCTION("""COMPUTED_VALUE"""),2.0) -> 2
A35: =IFERROR(__xludf.DUMMYFUNCTION("""COMPUTED_VALUE"""),63.0) -> 63 | B35: =IFERROR(__xludf.DUMMYFUNCTION("""COMPUTED_VALUE"""),"Vendor") -> Vendor | C35: =IFERROR(__xludf.DUMMYFUNCTION("""COMPUTED_VALUE"""),"receive an email notification if my request to apply to join a bazaar or apply for a booth has been accepted/rejected") -> receive an email notification if my request to apply to join a bazaar or apply for a booth has been accepted/rejected | E35: =IFERROR(__xludf.DUMMYFUNCTION("""COMPUTED_VALUE"""),2.0) -> 2 | F35: =IFERROR(__xludf.DUMMYFUNCTION("""COMPUTED_VALUE"""),2.0) -> 2
A36: =IFERROR(__xludf.DUMMYFUNCTION("""COMPUTED_VALUE"""),64.0) -> 64 | B36: =IFERROR(__xludf.DUMMYFUNCTION("""COMPUTED_VALUE"""),"Vendor") -> Vendor | C36: =IFERROR(__xludf.DUMMYFUNCTION("""COMPUTED_VALUE"""),"pay participation fees for bazaar/booth upon acceptance of the request") -> pay participation fees for bazaar/booth upon acceptance of the request | D36: =IFERROR(__xludf.DUMMYFUNCTION("""COMPUTED_VALUE"""),"for booth: based on duration and location, for bazaar, based on location and booth size. Deadline for payment for vendor must be 3 days after receiving the acceptance email") -> for booth: based on duration and location, for bazaar, based on location and booth size. Deadline for payment for vendor must be 3 days after receiving the acceptance email | E36: =IFERROR(__xludf.DUMMYFUNCTION("""COMPUTED_VALUE"""),2.0) -> 2 | F36: =IFERROR(__xludf.DUMMYFUNCTION("""COMPUTED_VALUE"""),2.0) -> 2
A37: =IFERROR(__xludf.DUMMYFUNCTION("""COMPUTED_VALUE"""),65.0) -> 65 | B37: =IFERROR(__xludf.DUMMYFUNCTION("""COMPUTED_VALUE"""),"Vendor") -> Vendor | C37: =IFERROR(__xludf.DUMMYFUNCTION("""COMPUTED_VALUE"""),"receive a payment receipt via email upon paying") -> receive a payment receipt via email upon paying | E37: =IFERROR(__xludf.DUMMYFUNCTION("""COMPUTED_VALUE"""),2.0) -> 2 | F37: =IFERROR(__xludf.DUMMYFUNCTION("""COMPUTED_VALUE"""),2.0) -> 2
A38: =IFERROR(__xludf.DUMMYFUNCTION("""COMPUTED_VALUE"""),66.0) -> 66 | B38: =IFERROR(__xludf.DUMMYFUNCTION("""COMPUTED_VALUE"""),"Vendor") -> Vendor | C38: =IFERROR(__xludf.DUMMYFUNCTION("""COMPUTED_VALUE"""),"receive QR code for all registered visitors coming to the bazaar/booth via email") -> receive QR code for all registered visitors coming to the bazaar/booth via email | E38: =IFERROR(__xludf.DUMMYFUNCTION("""COMPUTED_VALUE"""),2.0) -> 2 | F38: =IFERROR(__xludf.DUMMYFUNCTION("""COMPUTED_VALUE"""),2.0) -> 2
A39: =IFERROR(__xludf.DUMMYFUNCTION("""COMPUTED_VALUE"""),67.0) -> 67 | B39: =IFERROR(__xludf.DUMMYFUNCTION("""COMPUTED_VALUE"""),"Vendor") -> Vendor | C39: =IFERROR(__xludf.DUMMYFUNCTION("""COMPUTED_VALUE"""),"cancel my participation request") -> cancel my participation request | D39: =IFERROR(__xludf.DUMMYFUNCTION("""COMPUTED_VALUE"""),"this can only happen if the vendor has not paid yet") -> this can only happen if the vendor has not paid yet | E39: =IFERROR(__xludf.DUMMYFUNCTION("""COMPUTED_VALUE"""),2.0) -> 2 | F39: =IFERROR(__xludf.DUMMYFUNCTION("""COMPUTED_VALUE"""),2.0) -> 2
A40: =IFERROR(__xludf.DUMMYFUNCTION("""COMPUTED_VALUE"""),70.0) -> 70 | B40: =IFERROR(__xludf.DUMMYFUNCTION("""COMPUTED_VALUE"""),"Vendor") -> Vendor | C40: =IFERROR(__xludf.DUMMYFUNCTION("""COMPUTED_VALUE"""),"apply to participate in GUC loyalty program by filling form that includes discount rate,promo code, terms and conditions") -> apply to participate in GUC loyalty program by filling form that includes discount rate,promo code, terms and conditions | E40: =IFERROR(__xludf.DUMMYFUNCTION("""COMPUTED_VALUE"""),2.0) -> 2 | F40: =IFERROR(__xludf.DUMMYFUNCTION("""COMPUTED_VALUE"""),2.0) -> 2
...

Sheet Non-functional Requirements
B1: NOTE: UI AND UX GRADING WILL BE SUBJECTIVE (BASED ON OPINION OF ASSIGNED PRODUCT MANAGER)
B2: UX | C2: Sprint # | D2: Out of | E2: Comments
A3: 1 | B3: Information Architecture | C3: 3 | D3: 20 | E3: Information layout on pages are divided properly, not a lot of whitepaces, no random buttons, menus are created correctly
A4: 2 | B4: Feedback and Responsiveness | C4: 3 | D4: 5
A5: 3 | B5: Navigation is Reversible | C5: 3 | D5: 5 | E5: DO NOT rely on the back button of the browser! 1 mark pre non-revisrsible page
A6: 4 | B6: Learnability | C6: 3 | D6: 5
A7: 5 | B7: Visibility | C7: 3 | D7: 5
A8: 6 | B8: Efficiency | C8: 3 | D8: 5
A9: 7 | B9: Design for errors | C9: 3 | D9: 10
A10: 8 | B10: Satisfaction | C10: 3 | D10: 5
D11: 60
B13: UI | C13: Sprint # | D13: Out of | E13: Comments
A14: 1 | B14: UI elements | C14: 3 | D14: 10 | E14: Menus, buttons, tables, etc.. are symmetric and consistent
A15: 2 | B15: UI looks professional | C15: 3 | D15: 10
D16: 20
B20: Smooth app flow (all past requirements are working) | C20: 3 | D20: 20 | E20: A max of 20 marks can be lost if any requirements completed in previous sprint but are no longer working. 1 mark per not working requirement.
B24: Total | D24: 100
